Workbook

Sheet Synthèse
B2: CAHIER DE RECETTE — LIVRIAL
B3: Groupe Atrial — Application de gestion des tournées de livraison
B5: INFORMATIONS GÉNÉRALES
B6: Application | C6: LIVRIAL
B7: Client | C7: Groupe Atrial (menuiserie industrielle BtoB, Brignoles — 83)
B8: URL testée | C8: https://livria.vercel.app/
B9: Environnement | C9: Production Vercel — Base de données Supabase (EU, Frankfurt)
B10: Rôles couverts | C10: LIVREUR · MAGASIN · ADV · ADMIN
B11: Rédacteur | C11: MIA — Médiation Intelligence Appliquée
B12: Date de création | C12: 09/07/2026
B13: Version du document | C13: V2
B14: Dernière mise à jour | C14: 04/08/2026
B15: COMPTES DE TEST
B16: Rôle | C16: Email | D16: Mot de passe
B17: ADMIN | C17: admin@atrial.fr | D17: Admin123
B18: ADV | C18: adv@atrial.fr | D18: Adv123
B19: LIVREUR | C19: livreur@atrial.fr | D19: Livreur123
B20: MAGASIN | C20: (compte à créer via Admin — rôle MAGASIN) | D20: —
B22: LÉGENDE STATUT
B23: OK | C23: Test réussi, conforme au résultat attendu
B24: KO | C24: Test en échec, bug bloquant ou majeur
B25: Partiel | C25: Fonctionne avec réserve, anomalie mineure ou point à vérifier
B26: Non testé | C26: Test pas encore exécuté
B28: LÉGENDE PRIORITÉ
B29: P1 | C29: Bloquant — doit être corrigé avant mise en main terrain
B30: P2 | C30: Important — à corriger avant mise en production
B31: P3 | C31: Amélioration UX — non bloquant
B33: SYNTHÈSE DES RÉSULTATS (mise à jour automatique)
B34: Module | C34: OK | D34: KO | E34: Partiel | F34: Non testé | G34: Total
B35: AUTH | C35: =COUNTIF(AUTH!$G$6:$G$200,"OK") | D35: =COUNTIF(AUTH!$G$6:$G$200,"KO") | E35: =COUNTIF(AUTH!$G$6:$G$200,"Partiel") | F35: =COUNTIF(AUTH!$G$6:$G$200,"Non testé") | G35: =SUM(C35:F35)
B36: LIVREUR | C36: =COUNTIF(LIVREUR!$G$6:$G$200,"OK") | D36: =COUNTIF(LIVREUR!$G$6:$G$200,"KO") | E36: =COUNTIF(LIVREUR!$G$6:$G$200,"Partiel") | F36: =COUNTIF(LIVREUR!$G$6:$G$200,"Non testé") | G36: =SUM(C36:F36)
B37: MAGASIN | C37: =COUNTIF(MAGASIN!$G$6:$G$200,"OK") | D37: =COUNTIF(MAGASIN!$G$6:$G$200,"KO") | E37: =COUNTIF(MAGASIN!$G$6:$G$200,"Partiel") | F37: =COUNTIF(MAGASIN!$G$6:$G$200,"Non testé") | G37: =SUM(C37:F37)
B38: ADV | C38: =COUNTIF(ADV!$G$6:$G$200,"OK") | D38: =COUNTIF(ADV!$G$6:$G$200,"KO") | E38: =COUNTIF(ADV!$G$6:$G$200,"Partiel") | F38: =COUNTIF(ADV!$G$6:$G$200,"Non testé") | G38: =SUM(C38:F38)
B39: ADMIN | C39: =COUNTIF(ADMIN!$G$6:$G$200,"OK") | D39: =COUNTIF(ADMIN!$G$6:$G$200,"KO") | E39: =COUNTIF(ADMIN!$G$6:$G$200,"Partiel") | F39: =COUNTIF(ADMIN!$G$6:$G$200,"Non testé") | G39: =SUM(C39:F39)
B40: PLANNING | C40: =COUNTIF(PLANNING!$G$6:$G$200,"OK") | D40: =COUNTIF(PLANNING!$G$6:$G$200,"KO") | E40: =COUNTIF(PLANNING!$G$6:$G$200,"Partiel") | F40: =COUNTIF(PLANNING!$G$6:$G$200,"Non testé") | G40: =SUM(C40:F40)
B41: Webhook Make | C41: =COUNTIF('Webhook Make'!$G$6:$G$200,"OK") | D41: =COUNTIF('Webhook Make'!$G$6:$G$200,"KO") | E41: =COUNTIF('Webhook Make'!$G$6:$G$200,"Partiel") | F41: =COUNTIF('Webhook Make'!$G$6:$G$200,"Non testé") | G41: =SUM(C41:F41)
B42: Non-régression | C42: =COUNTIF('Non-régression'!$G$6:$G$200,"OK") | D42: =COUNTIF('Non-régression'!$G$6:$G$200,"KO") | E42: =COUNTIF('Non-régression'!$G$6:$G$200,"Partiel") | F42: =COUNTIF('Non-régression'!$G$6:$G$200,"Non testé") | G42: =SUM(C42:F42)
B43: TOTAL | C43: =SUM(C35:C42) | D43: =SUM(D35:D42) | E43: =SUM(E35:E42) | F43: =SUM(F35:F42) | G43: =SUM(G35:G42)
B45: PÉRIMÈTRE DE LA VERSION V2
B46: Évolutions couvertes | C46: Référence affaire dans le planning · mode écran · fermeture des modales ADV · vue semaine et brouillons magasin · itinéraire turn-by-turn livreur · saisie des colis livrés (commit b0b7836)
...

Sheet AUTH
B2: AUTH — Authentification
B3: Connexion, déconnexion, gestion des sessions et isolation des rôles
B5: ID | C5: Scénario de test | D5: Étapes | E5: Résultat attendu | F5: Résultat obtenu | G5: Statut | H5: Priorité | I5: Testeur | J5: Date | K5: Commentaire
B6: AUTH-01 | C6: Connexion valide — 4 rôles | D6: Se connecter successivement avec les comptes ADMIN, ADV, LIVREUR et MAGASIN. | E6: Chaque rôle est authentifié et redirigé vers sa vue dédiée (/admin, /adv, /livreur, /magasin). | H6: P1
B7: AUTH-02 | C7: Connexion invalide | D7: Saisir un email ou un mot de passe incorrect. Tenter de soumettre le formulaire avec des champs vides. | E7: Un message « Identifiants incorrects » s'affiche. Les champs vides bloquent la soumission côté client. | H7: P1
B8: AUTH-03 | C8: Déconnexion — toutes vues | D8: Depuis chaque vue (LIVREUR, MAGASIN, ADV, ADMIN), chercher et utiliser le bouton de déconnexion. | E8: Un bouton de déconnexion est visible et accessible dans les 4 vues. La session est détruite après clic. | H8: P1
B9: AUTH-04 | C9: Isolation des rôles | D9: Connecté en LIVREUR, tenter d'accéder à /adv et /admin via l'URL. Répéter pour les autres rôles. | E9: L'accès est refusé (redirection) pour toute vue non autorisée par le rôle. | H9: P1
B10: AUTH-05 | C10: Persistance de session | D10: Se connecter, puis recharger la page (F5) ou fermer/rouvrir l'onglet. | E10: L'utilisateur reste connecté et sur sa vue, sans nouvelle demande d'identifiants. | H10: P2
B11: AUTH-06 | C11: Expiration de session (TTL 8h) | D11: Attendre l'expiration de la session (8h) ou simuler un cookie expiré, puis effectuer une action. | E11: L'utilisateur est redirigé vers la page de connexion. | H11: P3
B12: AUTH-07 | C12: Effacement du message d'erreur | D12: Après un échec de connexion, ressaisir des identifiants dans les champs. | E12: Le message « Identifiants incorrects » disparaît dès la modification des champs. | H12: P3

Sheet LIVREUR
B2: LIVREUR — Vue mobile terrain
B3: Tournée du jour, carte, statuts et actions livreur
B5: ID | C5: Scénario de test | D5: Étapes | E5: Résultat attendu | F5: Résultat obtenu | G5: Statut | H5: Priorité | I5: Testeur | J5: Date | K5: Commentaire
B6: L-01 | C6: Liste des stops du jour | D6: Se connecter en LIVREUR et consulter la liste des stops. | E6: Société, adresse, téléphone (lien tel:), numéro d'affaire, badges PVC/ALU/MIXTE, lien livraison groupée, nombre de colis, emplacement et commentaire magasin sont affichés. | H6: P1
B7: L-02 | C7: Stop non préparé par le magasin | D7: Consulter un stop dont la préparation magasin n'est pas validée. | E7: Le stop affiche la mention « En attente de préparation magasin ». | H7: P2
B8: L-03 | C8: Carte et marqueurs | D8: Observer la carte en haut de la vue tournée. | E8: La carte se charge correctement et affiche un marqueur coloré par stop, cliquable. | H8: P1
B9: L-04 | C9: Fiche détail d'un stop | D9: Ouvrir un stop pour afficher sa fiche détail. | E9: Toutes les informations du stop sont visibles, ainsi que la case à cocher de prise en charge des colis. | H9: P1
B10: L-05 | C10: Galerie photos de colissage | D10: Dans la fiche détail, consulter les photos ajoutées par le magasin. | E10: Les photos sont visibles et accessibles (scroll complet), sans être masquées par un bouton d'action. | H10: P2
B11: L-06 | C11: Changement de statut — cycle complet | D11: Depuis un stop « À livrer », cocher la prise en charge des colis, passer en « En cours », puis en « Livré ». | E11: Le démarrage est bloqué sans la case cochée. Chaque changement de statut est confirmé et les compteurs sont mis à jour. | H11: P1
B12: L-07 | C12: Retour en arrière sur un stop « Livré » | D12: Depuis un stop marqué « Livré », chercher une action pour annuler/revenir en arrière. | E12: Une action « Annuler la livraison » permet de repasser le stop en statut précédent. | H12: P2
B13: L-08 | C13: Optimisation de l'itinéraire | D13: Cliquer sur « Optimiser l'itinéraire ». | E13: L'ordre des stops est recalculé et affiché, avec un indicateur de chargement pendant le traitement. | H13: P3
B14: L-09 | C14: Impression de la tournée | D14: Cliquer sur « Imprimer ». | E14: La mise en page imprimée présente la tournée du jour de façon lisible et complète. | H14: P3
B15: L-10 | C15: Livraison groupée | D15: Ouvrir un stop marqué comme faisant partie d'une livraison groupée (lien 🔗). | E15: Les stops liés sont identifiables et accessibles depuis la fiche. | H15: P3
B16: L-11 | C16: Fermeture de la fiche détail | D16: Ouvrir la fiche détail d'un stop puis tenter de la fermer (touche Échap, glissement du bandeau, bouton fermer). | E16: La fiche se ferme par au moins deux méthodes intuitives (glissement + bouton visible), pas seulement en touchant l'arrière-plan. | H16: P3
B17: L-12 | C17: Boutons « Optimiser » et « Imprimer » | D17: Afficher la vue LIVREUR sur mobile puis sur desktop, et observer les deux boutons en bas de l'écran. | E17: Les deux boutons sont côte à côte (ou l'un sous l'autre si l'écran est étroit), entièrement cliquables, sans aucun chevauchement ni superposition. | H17: P1
... B25: L-20 | C25: Échec d'enregistrement des colis livrés | D25: Couper le réseau, saisir un nombre de colis puis cliquer sur « Marquer comme livré ». | E25: Une confirmation explicite prévient que le nombre n'a pas pu être enregistré et laisse le choix de marquer ou non le stop comme livré. En cas de refus, le stop conserve son statut « En cours ». | H25: P2

Sheet MAGASIN
B2: MAGASIN — Préparation des livraisons
B3: Validation des stops, saisie colis et upload photos
B5: ID | C5: Scénario de test | D5: Étapes | E5: Résultat attendu | F5: Résultat obtenu | G5: Statut | H5: Priorité | I5: Testeur | J5: Date | K5: Commentaire
B6: M-01 | C6: Liste des stops magasin | D6: Se connecter en MAGASIN et consulter les onglets « Aujourd'hui » et « Demain ». | E6: Les compteurs TOTAL / PRÊTS / À PRÉPARER sont exacts et la liste complète des stops s'affiche. | H6: P1
B7: M-02 | C7: Validation d'un stop + saisie colis | D7: Saisir le nombre de colis, l'emplacement et un commentaire, puis valider le stop. | E7: Les données sont enregistrées, le statut passe à « Prêt » et les compteurs sont mis à jour (toast de confirmation). | H7: P1
B8: M-03 | C8: Upload de photo de colissage | D8: Ajouter une photo lors de la préparation d'un stop, vérifier l'aperçu, puis la supprimer. | E8: L'upload fonctionne, un aperçu s'affiche immédiatement, la suppression est possible et la photo est bien enregistrée à la validation. | H8: P1
B9: M-04 | C9: Transmission des données au livreur | D9: Valider un stop côté MAGASIN (colis, emplacement, commentaire, photo), puis consulter le même stop côté LIVREUR. | E9: Toutes les informations saisies côté magasin apparaissent correctement dans la fiche livreur. | H9: P1
B10: M-05 | C10: Réédition d'un stop « Prêt » | D10: Tenter de rouvrir et modifier un stop déjà validé « Prêt » (ex. corriger le nombre de colis). | E10: Un bouton « Modifier » permet de rouvrir et corriger un stop déjà préparé. | H10: P2
B11: M-06 | C11: Vue semaine — affichage et navigation | D11: Se connecter en MAGASIN, ouvrir l'onglet « Semaine », puis naviguer avec ‹ , › et « Cette semaine ». | E11: Les 7 jours s'affichent en colonnes, du lundi au dimanche, avec le libellé de la semaine, un compteur « prêts / total » par jour et le jour courant mis en évidence. | H11: P1
B12: M-07 | C12: Vue semaine — contenu des cartes | D12: Observer les cartes d'une journée chargée dans la vue semaine. | E12: Chaque carte affiche le numéro d'affaire, la société, la tournée, et le cas échéant le type produit, le nombre de colis, l'emplacement, le nombre de photos et la mention « Brouillon ». La bordure gauche est colorée selon l'état de préparation. | H12: P2
B13: M-08 | C13: Ouverture de la fiche depuis la vue semaine | D13: Cliquer sur une carte dans la vue semaine. | E13: La fiche de préparation s'ouvre, pré-remplie, et rappelle la date de livraison du stop. Après enregistrement, la vue semaine est mise à jour sans rechargement de page. | H13: P1
B14: M-09 | C14: Enregistrement d'une préparation incomplète | D14: Ouvrir une fiche, saisir uniquement l'emplacement (sans le nombre de colis), cliquer sur « Enregistrer », puis fermer la fiche et la rouvrir. | E14: L'enregistrement est accepté sans exiger le nombre de colis. Le stop passe en « Brouillon » (et non « Prêt »), et l'emplacement saisi est bien restitué à la réouverture. | H14: P1
B15: M-10 | C15: Reprise puis validation d'un brouillon | D15: Rouvrir un stop en « Brouillon », compléter le nombre de colis et le commentaire, puis cliquer sur « Valider — colis prêts ». | E15: Les données déjà saisies sont conservées, la validation passe le stop en « Prêt », les compteurs sont mis à jour et le livreur voit l'information. | H15: P1
B16: M-11 | C16: Validation impossible sans nombre de colis | D16: Ouvrir une fiche vide et cliquer directement sur « Valider — colis prêts ». | E16: La validation est refusée avec un message explicite invitant à utiliser « Enregistrer » pour reprendre plus tard. Aucun stop n'est marqué « Prêt ». | H16: P2
B17: M-12 | C17: Photos ajoutées en mode brouillon | D17: Ajouter une photo, cliquer sur « Enregistrer » (sans valider), puis rouvrir la fiche. | E17: La photo est bien téléversée et visible à la réouverture, alors que le stop reste en « Brouillon ». | H17: P2

Sheet ADV
B2: ADV — Console de pilotage
B3: Tableau de bord, création et gestion des tournées
B5: ID | C5: Scénario de test | D5: Étapes | E5: Résultat attendu | F5: Résultat obtenu | G5: Statut | H5: Priorité | I5: Testeur | J5: Date | K5: Commentaire
B6: A-01 | C6: Tableau de bord et filtres | D6: Consulter le tableau ADV, tester les filtres ATRIAL / Enlèvement / Transporteur / Tous et la carte. | E6: Le tableau affiche toutes les colonnes (dont la date de livraison), les filtres fonctionnent et la carte affiche des marqueurs colorés par statut. | H6: P1
B7: A-02 | C7: Création d'un stop + géocodage | D7: Créer un nouveau stop via « + Nouvelle livraison » avec une adresse complète. | E7: Le stop est créé et affiché immédiatement, avec géocodage automatique (coordonnées attribuées sans action manuelle). | H7: P1
B8: A-03 | C8: Synchronisation TYPE / TOURNÉE | D8: Créer ou modifier un stop en choisissant une tournée « Enlèvement » ou « Transporteur ». | E8: Le champ TYPE se met à jour automatiquement en cohérence avec la tournée choisie. | H8: P2
B9: A-04 | C9: Modification tournée / véhicule | D9: Modifier la tournée et le véhicule (PL/VL) d'un stop existant. | E9: Le changement est enregistré (auto-save ou bouton dédié) et persiste après rechargement de la page. | H9: P2
B10: A-05 | C10: Report d'un stop | D10: Utiliser l'icône calendrier pour reporter un stop à une nouvelle date. | E10: Une modale de confirmation s'affiche, le stop quitte la liste du jour et apparaît à la nouvelle date. | H10: P2
B11: A-06 | C11: Suppression d'un stop | D11: Supprimer un stop de test. | E11: Une confirmation explicite (« action irréversible ») est demandée avant suppression effective. | H11: P2
B12: A-07 | C12: Annulation de statut | D12: Sur un stop « Livré », utiliser l'action « Annuler » depuis le tableau ADV. | E12: Le stop repasse au statut « À livrer ». | H12: P2
B13: A-08 | C13: Navigation par date | D13: Chercher un sélecteur de date pour consulter les stops d'un autre jour que le jour en cours. | E13: Un sélecteur de date permet de naviguer entre les jours (pas uniquement le jour en cours). | H13: P3
B14: A-09 | C14: Fermeture de la modale « Nouvelle livraison » | D14: Ouvrir « + Nouvelle livraison » sans rien saisir, puis la fermer successivement par la croix en haut à droite, par un clic sur le fond sombre, et par la touche Échap. | E14: Les trois méthodes ferment la modale. Aucune saisie n'est requise pour pouvoir la quitter et la vue ADV reste utilisable. | H14: P1
B15: A-10 | C15: Fermeture des autres modales ADV | D15: Répéter le test A-09 sur les modales « Planifier ce stop », « Supprimer ce stop » et « Reporter ce stop ». | E15: Chaque modale dispose d'une croix et se ferme aussi par clic sur le fond ou touche Échap, sans déclencher l'action associée. | H15: P2
B16: A-11 | C16: Modale sur écran de faible hauteur | D16: Réduire la hauteur de la fenêtre puis ouvrir « + Nouvelle livraison ». | E16: Le contenu de la modale défile et les boutons d'action restent atteignables ; la croix de fermeture reste visible. | H16: P3
B17: A-12 | C17: Référence client et numéro d'affaire | D17: Créer un stop en renseignant le numéro d'affaire et la référence client, puis consulter l'onglet Planning. | E17: Le numéro d'affaire et la référence client remontent bien dans la vue Planning à la date de livraison choisie. | H17: P2

Sheet ADMIN
B2: ADMIN — Administration
B3: Gestion des utilisateurs, debug stops et supervision
B5: ID | C5: Scénario de test | D5: Étapes | E5: Résultat attendu | F5: Résultat obtenu | G5: Statut | H5: Priorité | I5: Testeur | J5: Date | K5: Commentaire
B6: AD-01 | C6: Gestion des utilisateurs | D6: Créer un nouvel utilisateur, le révoquer, puis le réactiver. | E6: Chaque action se reflète immédiatement dans la liste et dans les compteurs (actifs / révoqués). | H6: P1
B7: AD-02 | C7: Réinitialisation de mot de passe | D7: Réinitialiser le mot de passe d'un utilisateur test. | E7: Un mot de passe temporaire est communiqué (affiché à l'admin et/ou envoyé par email à l'utilisateur), pas seulement un message de confirmation. | H7: P1
B8: AD-03 | C8: Debug stops | D8: Sélectionner une date, ouvrir un stop et modifier ses champs, puis sauvegarder. | E8: Tous les champs sont modifiables et la sauvegarde est confirmée (« Stop mis à jour »). | H8: P2
B9: AD-04 | C9: Géocoder les stops manquants | D9: Cliquer sur « Géocoder manquants ». | E9: Une requête est déclenchée et un retour visuel indique le nombre de stops géocodés (ou « 0 stop à géocoder »). | H9: P2
B10: AD-05 | C10: Logs d'activité | D10: Effectuer plusieurs actions (connexion, changement de statut, création/suppression de stop) puis consulter la page « Logs d'activité ». | E10: Les actions réalisées apparaissent dans la liste des logs. | H10: P2
B11: AD-06 | C11: Sélecteur de date (Debug stops / Report) | D11: Saisir une date au clavier dans le sélecteur, en particulier sur le segment « année ». | E11: Le segment année se remplace correctement à la saisie (pas d'accumulation de chiffres type « 275760 »), la liste reste cohérente. | H11: P2

Sheet PLANNING
B2: PLANNING — Vue d'ensemble des livraisons
B3: Planning semaine / mois / trimestre, référence affaire et mode écran
B5: ID | C5: Scénario de test | D5: Étapes | E5: Résultat attendu | F5: Résultat obtenu | G5: Statut | H5: Priorité | I5: Testeur | J5: Date | K5: Commentaire
B6: P-01 | C6: Accès au planning (ADV et ADMIN) | D6: Ouvrir l'onglet « Planning » depuis la console ADV, puis depuis la console ADMIN. | E6: Le planning s'affiche dans les deux consoles avec les mêmes données. | H6: P1
B7: P-02 | C7: Vues semaine / mois / trimestre | D7: Basculer entre les trois vues et naviguer avec ‹ , › et « Aujourd'hui ». | E7: Chaque vue affiche la bonne période, le nombre de stops par jour, et la navigation revient correctement sur la période courante. | H7: P1
B8: P-03 | C8: Affichage de la référence affaire | D8: En vue semaine, observer une journée comportant plusieurs livraisons. | E8: Chaque livraison affiche son numéro d'affaire (« N° 2026-089 ») avec, en dessous, la référence client ou la société. Les stops sans numéro d'affaire restent affichés avec leur client seul. | H8: P1
B9: P-04 | C9: Code couleur par statut | D9: Comparer, sur une même journée, des stops à livrer, en cours et livrés. | E9: La bordure gauche de chaque ligne reprend la couleur du statut, cohérente avec la barre de progression du jour. | H9: P2
B10: P-05 | C10: Journée très chargée | D10: Consulter une journée comportant plus de 4 livraisons en vue semaine (hors mode écran). | E10: Les 4 premières livraisons sont listées puis la mention « +N autres » indique le reste, sans déformer la cellule. | H10: P3
B11: P-06 | C11: Détail au survol en vue mois | D11: Survoler une journée renseignée en vue mois. | E11: Une infobulle liste les numéros d'affaire et clients du jour. | H11: P3
B12: P-07 | C12: Activation du mode écran | D12: Cliquer sur « 🖥 Mode écran ». | E12: L'affichage passe en plein écran, le menu latéral et la barre supérieure disparaissent, la typographie est agrandie et toutes les livraisons du jour sont affichées sans troncature. | H12: P1
B13: P-08 | C13: Bandeau de synthèse du mode écran | D13: En mode écran, contrôler le bandeau supérieur. | E13: Le bandeau affiche le total de stops de la période, les livrés avec leur pourcentage, les en cours, les à livrer, ainsi que l'heure courante mise à jour chaque minute. | H13: P2
B14: P-09 | C14: Rafraîchissement automatique | D14: Laisser le mode écran actif, faire évoluer un statut depuis une autre session, puis attendre une minute. | E14: Le planning se met à jour seul, sans intervention ni rechargement manuel. | H14: P1
B15: P-10 | C15: Sortie du mode écran | D15: Quitter le mode écran par la touche Échap, puis une seconde fois par le bouton « ✕ Quitter l'écran ». | E15: Les deux méthodes restaurent l'affichage normal (menu et barre supérieure de retour) et arrêtent le rafraîchissement automatique. | H15: P2
B16: P-11 | C16: Lisibilité sur écran de diffusion | D16: Afficher le mode écran sur l'écran destiné aux salariés, à la distance de lecture réelle. | E16: Numéros d'affaire, clients et compteurs sont lisibles depuis le poste de travail ; rien n'est coupé en bas de l'écran. | H16: P2

Sheet Webhook Make
B2: WEBHOOK MAKE — Intégration entrante
B3: Réception des stops via POST /api/webhook/stop
B5: ID | C5: Scénario de test | D5: Étapes | E5: Résultat attendu | F5: Résultat obtenu | G5: Statut | H5: Priorité | I5: Testeur | J5: Date | K5: Commentaire
B6: W-01 | C6: Réception webhook — données complètes | D6: Envoyer une requête POST sur /api/webhook/stop avec un JSON complet (société, adresse, téléphone, coordonnées, numéro d'affaire, type). | E6: Réponse 200 avec un identifiant de stop créé. Le stop apparaît côté ADV et LIVREUR. | H6: P1
B7: W-02 | C7: Types de livraison acceptés | D7: Envoyer un webhook pour chacun des trois types : ATRIAL, ENLEVEMENT, TRANSPORTEUR. | E7: Les trois types sont acceptés et le stop créé porte le type correspondant. | H7: P2
B8: W-03 | C8: Données manquantes ou invalides | D8: Envoyer un webhook avec des champs obligatoires manquants ou mal formés. | E8: Réponse 400 avec un message d'erreur explicite, aucun stop n'est créé. | H8: P2

Sheet Non-régression
B2: NON-RÉGRESSION
B3: Re-vérification des bugs identifiés lors du test du 21/06/2026
B5: ID | C5: Scénario de test | D5: Étapes | E5: Résultat attendu | F5: Résultat obtenu | G5: Statut | H5: Priorité | I5: Testeur | J5: Date | K5: Commentaire
B6: NR-01 | C6: BUG-001 — Carte Google Maps livreur | D6: Se connecter en LIVREUR et observer la carte. | E6: La carte s'affiche correctement avec des marqueurs, sans erreur « BillingNotEnabledMapError » ni filigrane « For development purposes only ». | H6: P1 | K6: Corrigé lors du test du 21/06/2026 (facturation Google Maps ou migration Leaflet).
B7: NR-02 | C7: BUG-002 — Déconnexion LIVREUR/MAGASIN | D7: Se connecter en LIVREUR puis en MAGASIN et chercher le bouton de déconnexion. | E7: Un bouton de déconnexion est présent et fonctionnel dans les deux vues. | H7: P1
B8: NR-03 | C8: BUG-P2-001 — Annulation d'un stop Livré | D8: Marquer un stop « Livré » côté LIVREUR puis chercher une action d'annulation. | E8: Une action « Annuler la livraison » est disponible. | H8: P2
B9: NR-04 | C9: BUG-P2-002 — Géocodage automatique à la création | D9: Créer un stop côté ADV sans géocoder manuellement. | E9: Le stop obtient des coordonnées automatiquement, sans passer par « à planifier ». | H9: P2
B10: NR-05 | C10: BUG-P2-003 — Synchronisation TYPE/TOURNÉE | D10: Choisir une tournée « Enlèvement » ou « Transporteur » à la création/modification d'un stop. | E10: Le TYPE se met à jour automatiquement, y compris via le clavier. | H10: P2
B11: NR-06 | C11: BUG-P2-004 — Bouton « Géocoder manquants » | D11: Cliquer sur « Géocoder manquants » côté ADMIN. | E11: Une requête réseau est déclenchée et un retour visuel (nombre de stops géocodés) s'affiche. | H11: P2
B12: NR-07 | C12: BUG-P2-005 — Journalisation des logs | D12: Effectuer des actions puis consulter « Logs d'activité ». | E12: Les actions sont enregistrées et visibles dans les logs. | H12: P2
B13: NR-08 | C13: BUG-P2-006 — Galerie photos masquée | D13: Ouvrir la fiche détail d'un stop avec photo de colissage côté LIVREUR. | E13: La galerie photos est visible et accessible, non masquée par le bouton d'action. | H13: P2
B14: NR-09 | C14: BUG-P2-007 — Communication du mot de passe réinitialisé | D14: Réinitialiser le mot de passe d'un utilisateur test côté ADMIN. | E14: Le nouveau mot de passe est communiqué (affiché et/ou envoyé par email), pas seulement un message de confirmation. | H14: P1
B15: NR-10 | C15: UX-005 — Cohérence nom / domaine | D15: Vérifier le nom affiché de l'application et l'URL de déploiement. | E15: Le nom « LIVRIAL » et le domaine sont cohérents. | H15: P3
B16: NR-11 | C16: UX-006 — Boutons livreur superposés | D16: Vue LIVREUR sur mobile et sur desktop : observer « Optimiser l'itinéraire » et « Imprimer ». | E16: Les deux boutons sont distincts et cliquables séparément. | H16: P1 | K16: Corrigé le 04/08/2026 (commit b0b7836) — les deux boutons étaient en position fixe au même emplacement.
B17: NR-12 | C17: UX-007 — Modale « Nouvelle livraison » bloquée | D17: Ouvrir la modale ADV sans rien saisir et tenter de la fermer. | E17: La modale se ferme par la croix, par clic sur le fond ou par Échap. | H17: P1 | K17: Corrigé le 04/08/2026 (commit b0b7836) — seul le bouton « Annuler » permettait de sortir.
B18: NR-13 | C18: Migration base — colonne colis_livres | D18: Vérifier que la colonne colis_livres existe dans la table stops, puis saisir un nombre de colis livrés côté LIVREUR et recharger. | E18: La valeur est bien persistée en base et réaffichée après rechargement. | H18: P1 | K18: Prérequis : ALTER TABLE stops ADD COLUMN IF NOT EXISTS colis_livres INTEGER;
B19: NR-14 | C19: Limite de 12 fonctions Vercel Hobby | D19: Contrôler le déploiement Vercel après mise en ligne. | E19: Le déploiement réussit : l'itinéraire est servi par un handler GET sur /api/routing/optimize, sans créer de 13e fonction. | H19: P1
